{"primaryContentSections":[{"kind":"declarations","declarations":[{"tokens":[{"kind":"keyword","text":"case"},{"kind":"text","text":" "},{"kind":"identifier","text":"internalServerException"},{"kind":"text","text":"("},{"kind":"typeIdentifier","identifier":"doc:\/\/AWSAuditManager\/documentation\/AWSAuditManager\/InternalServerException","preciseIdentifier":"s:15AWSAuditManager23InternalServerExceptionV","text":"InternalServerException"},{"kind":"text","text":")"}],"languages":["swift"],"platforms":["macOS"]}]}],"schemaVersion":{"major":0,"minor":3,"patch":0},"sections":[],"variants":[{"paths":["\/documentation\/awsauditmanager\/getcontroloutputerror\/internalserverexception(_:)"],"traits":[{"interfaceLanguage":"swift"}]}],"identifier":{"url":"doc:\/\/AWSAuditManager\/documentation\/AWSAuditManager\/GetControlOutputError\/internalServerException(_:)","interfaceLanguage":"swift"},"kind":"symbol","metadata":{"fragments":[{"kind":"keyword","text":"case"},{"kind":"text","text":" "},{"kind":"identifier","text":"internalServerException"},{"kind":"text","text":"("},{"kind":"typeIdentifier","text":"InternalServerException","preciseIdentifier":"s:15AWSAuditManager23InternalServerExceptionV"},{"kind":"text","text":")"}],"title":"GetControlOutputError.internalServerException(_:)","roleHeading":"Case","role":"symbol","symbolKind":"case","externalID":"s:15AWSAuditManager21GetControlOutputErrorO23internalServerExceptionyAcA08InternalhI0VcACmF","modules":[{"name":"AWSAuditManager"}]},"hierarchy":{"paths":[["doc:\/\/AWSAuditManager\/documentation\/AWSAuditManager","doc:\/\/AWSAuditManager\/documentation\/AWSAuditManager\/GetControlOutputError"]]},"references":{"doc://AWSAuditManager/documentation/AWSAuditManager/GetControlOutputError/internalServerException(_:)":{"role":"symbol","title":"GetControlOutputError.internalServerException(_:)","fragments":[{"kind":"keyword","text":"case"},{"kind":"text","text":" "},{"kind":"identifier","text":"internalServerException"},{"kind":"text","text":"("},{"kind":"typeIdentifier","text":"InternalServerException","preciseIdentifier":"s:15AWSAuditManager23InternalServerExceptionV"},{"kind":"text","text":")"}],"abstract":[],"identifier":"doc:\/\/AWSAuditManager\/documentation\/AWSAuditManager\/GetControlOutputError\/internalServerException(_:)","kind":"symbol","type":"topic","url":"\/documentation\/awsauditmanager\/getcontroloutputerror\/internalserverexception(_:)"},"doc://AWSAuditManager/documentation/AWSAuditManager/GetControlOutputError":{"role":"symbol","title":"GetControlOutputError","fragments":[{"kind":"keyword","text":"enum"},{"kind":"text","text":" "},{"kind":"identifier","text":"GetControlOutputError"}],"abstract":[],"identifier":"doc:\/\/AWSAuditManager\/documentation\/AWSAuditManager\/GetControlOutputError","kind":"symbol","type":"topic","navigatorTitle":[{"kind":"identifier","text":"GetControlOutputError"}],"url":"\/documentation\/awsauditmanager\/getcontroloutputerror"},"doc://AWSAuditManager/documentation/AWSAuditManager/InternalServerException":{"role":"symbol","title":"InternalServerException","fragments":[{"kind":"keyword","text":"struct"},{"kind":"text","text":" "},{"kind":"identifier","text":"InternalServerException"}],"abstract":[{"type":"text","text":"An internal service error occurred during the processing of your request. Try again later."}],"identifier":"doc:\/\/AWSAuditManager\/documentation\/AWSAuditManager\/InternalServerException","kind":"symbol","type":"topic","navigatorTitle":[{"kind":"identifier","text":"InternalServerException"}],"url":"\/documentation\/awsauditmanager\/internalserverexception"},"doc://AWSAuditManager/documentation/AWSAuditManager":{"role":"collection","title":"AWSAuditManager","abstract":[],"identifier":"doc:\/\/AWSAuditManager\/documentation\/AWSAuditManager","kind":"symbol","type":"topic","url":"\/documentation\/awsauditmanager"}}}