{"primaryContentSections":[{"kind":"declarations","declarations":[{"tokens":[{"kind":"keyword","text":"case"},{"kind":"text","text":" "},{"kind":"identifier","text":"internalServerException"},{"kind":"text","text":"("},{"kind":"typeIdentifier","identifier":"doc:\/\/AWSAuditManager\/documentation\/AWSAuditManager\/InternalServerException","preciseIdentifier":"s:15AWSAuditManager23InternalServerExceptionV","text":"InternalServerException"},{"kind":"text","text":")"}],"languages":["swift"],"platforms":["macOS"]}]}],"schemaVersion":{"major":0,"minor":3,"patch":0},"sections":[],"variants":[{"paths":["\/documentation\/awsauditmanager\/listkeywordsfordatasourceoutputerror\/internalserverexception(_:)"],"traits":[{"interfaceLanguage":"swift"}]}],"identifier":{"url":"doc:\/\/AWSAuditManager\/documentation\/AWSAuditManager\/ListKeywordsForDataSourceOutputError\/internalServerException(_:)","interfaceLanguage":"swift"},"kind":"symbol","metadata":{"fragments":[{"kind":"keyword","text":"case"},{"kind":"text","text":" "},{"kind":"identifier","text":"internalServerException"},{"kind":"text","text":"("},{"kind":"typeIdentifier","text":"InternalServerException","preciseIdentifier":"s:15AWSAuditManager23InternalServerExceptionV"},{"kind":"text","text":")"}],"title":"ListKeywordsForDataSourceOutputError.internalServerException(_:)","roleHeading":"Case","role":"symbol","symbolKind":"case","externalID":"s:15AWSAuditManager36ListKeywordsForDataSourceOutputErrorO23internalServerExceptionyAcA08InternalkL0VcACmF","modules":[{"name":"AWSAuditManager"}]},"hierarchy":{"paths":[["doc:\/\/AWSAuditManager\/documentation\/AWSAuditManager","doc:\/\/AWSAuditManager\/documentation\/AWSAuditManager\/ListKeywordsForDataSourceOutputError"]]},"references":{"doc://AWSAuditManager/documentation/AWSAuditManager/ListKeywordsForDataSourceOutputError/internalServerException(_:)":{"role":"symbol","title":"ListKeywordsForDataSourceOutputError.internalServerException(_:)","fragments":[{"kind":"keyword","text":"case"},{"kind":"text","text":" "},{"kind":"identifier","text":"internalServerException"},{"kind":"text","text":"("},{"kind":"typeIdentifier","text":"InternalServerException","preciseIdentifier":"s:15AWSAuditManager23InternalServerExceptionV"},{"kind":"text","text":")"}],"abstract":[],"identifier":"doc:\/\/AWSAuditManager\/documentation\/AWSAuditManager\/ListKeywordsForDataSourceOutputError\/internalServerException(_:)","kind":"symbol","type":"topic","url":"\/documentation\/awsauditmanager\/listkeywordsfordatasourceoutputerror\/internalserverexception(_:)"},"doc://AWSAuditManager/documentation/AWSAuditManager/InternalServerException":{"role":"symbol","title":"InternalServerException","fragments":[{"kind":"keyword","text":"struct"},{"kind":"text","text":" "},{"kind":"identifier","text":"InternalServerException"}],"abstract":[{"type":"text","text":"An internal service error occurred during the processing of your request. Try again later."}],"identifier":"doc:\/\/AWSAuditManager\/documentation\/AWSAuditManager\/InternalServerException","kind":"symbol","type":"topic","navigatorTitle":[{"kind":"identifier","text":"InternalServerException"}],"url":"\/documentation\/awsauditmanager\/internalserverexception"},"doc://AWSAuditManager/documentation/AWSAuditManager/ListKeywordsForDataSourceOutputError":{"role":"symbol","title":"ListKeywordsForDataSourceOutputError","fragments":[{"kind":"keyword","text":"enum"},{"kind":"text","text":" "},{"kind":"identifier","text":"ListKeywordsForDataSourceOutputError"}],"abstract":[],"identifier":"doc:\/\/AWSAuditManager\/documentation\/AWSAuditManager\/ListKeywordsForDataSourceOutputError","kind":"symbol","type":"topic","navigatorTitle":[{"kind":"identifier","text":"ListKeywordsForDataSourceOutputError"}],"url":"\/documentation\/awsauditmanager\/listkeywordsfordatasourceoutputerror"},"doc://AWSAuditManager/documentation/AWSAuditManager":{"role":"collection","title":"AWSAuditManager","abstract":[],"identifier":"doc:\/\/AWSAuditManager\/documentation\/AWSAuditManager","kind":"symbol","type":"topic","url":"\/documentation\/awsauditmanager"}}}